Workbook
Name SegmentaçãodeDados_Classificação: #N/A
Name SegmentaçãodeDados_Classificação1: #N/A
Name SegmentaçãodeDados_Data__Mês: #N/A
Name SegmentaçãodeDados_Data__Mês1: #N/A
Name SegmentaçãodeDados_Data_de_envio__Mês: #N/A
Name SegmentaçãodeDados_Proposta_Enviada_?: #N/A
Name SegmentaçãodeDados_TIPO: #N/A

Sheet DASH

Sheet GERAL
A1: Data | B1: Nome | C1: Cliente | D1: Unidade | E1: Fonte | F1: Campanha | G1: Classificação | H1: Entrada | I1: Serviço | J1: Proposta Enviada ? | K1: Valor Proposta | L1: TIPO | M1: Data de envio | N1: Mês | O1: Semana Entrada | P1: Semana Envio
A2: 46035 | B2: Afranio | C2: Clariant | D2: Suzano | E2: Cliente ativo | F2: N/A | G2: B | H2: LS | I2: MED TRAB | J2: S | K2: 1650 | L2: P | M2: 46057 | N2: =UPPER(TEXT(A2,"MMMM")) -> JANEIRO | O2: =INT((DAY(A2)-1)/7)+1 & "ª semana" -> 2ª semana | P2: =INT((DAY(M2)-1)/7)+1 & "ª semana" -> 1ª semana
A3: 46037 | B3: Jéssica | C3: Rota das Bandeiras | D3: Corporativo | E3: CBQV | F3: N/A | G3: C | H3: LS | I3: GL | J3: S | K3: 16800 | L3: R | M3: 46042 | N3: =UPPER(TEXT(A3,"MMMM")) -> JANEIRO | O3: =INT((DAY(A3)-1)/7)+1 & "ª semana" -> 3ª semana | P3: =INT((DAY(M3)-1)/7)+1 & "ª semana" -> 3ª semana
A4: 46037 | B4: Priscila | C4: GLOBANT | D4: Corporativo | E4: Relacionamento | F4: N/A | G4: A | H4: JB | I4: ERGO | J4: S | K4: 26520 | L4: P | M4: 46045 | N4: =UPPER(TEXT(A4,"MMMM")) -> JANEIRO | O4: =INT((DAY(A4)-1)/7)+1 & "ª semana" -> 3ª semana | P4: =INT((DAY(M4)-1)/7)+1 & "ª semana" -> 4ª semana
A5: 46037 | B5: Sérgio | C5: Grupo Muffato | D5: SJRP | E5: E-mail | F5: N/A | G5: A | H5: LS | I5: ERGO | J5: S | K5: 29244 | L5: P | M5: 46037 | N5: =UPPER(TEXT(A5,"MMMM")) -> JANEIRO | O5: =INT((DAY(A5)-1)/7)+1 & "ª semana" -> 3ª semana | P5: =INT((DAY(M5)-1)/7)+1 & "ª semana" -> 3ª semana
A6: 46041 | B6: Paulo | C6: Spturis | D6: SP | E6: Busca Orgânica | F6: N/A | G6: C | H6: MKT | I6: GL | J6: S | K6: 65181.6 | L6: R | M6: 46041 | N6: =UPPER(TEXT(A6,"MMMM")) -> JANEIRO | O6: =INT((DAY(A6)-1)/7)+1 & "ª semana" -> 3ª semana | P6: =INT((DAY(M6)-1)/7)+1 & "ª semana" -> 3ª semana
A7: 46042 | B7: Gisele | C7: Assertiv | D7: SP | E7: Cliente ativo | F7: N/A | G7: C | H7: LS | I7: MASSO | J7: S | K7: 1900 | L7: P | M7: 46042 | N7: =UPPER(TEXT(A7,"MMMM")) -> JANEIRO | O7: =INT((DAY(A7)-1)/7)+1 & "ª semana" -> 3ª semana | P7: =INT((DAY(M7)-1)/7)+1 & "ª semana" -> 3ª semana
A8: 46042 | B8: Paulo | C8: Spturis | D8: SP | E8: Busca Orgânica | F8: N/A | G8: C | H8: MKT | I8: ERGO | J8: S | K8: 10079.28 | L8: R | M8: 46041 | N8: =UPPER(TEXT(A8,"MMMM")) -> JANEIRO | O8: =INT((DAY(A8)-1)/7)+1 & "ª semana" -> 3ª semana | P8: =INT((DAY(M8)-1)/7)+1 & "ª semana" -> 3ª semana
A9: 46043 | B9: Sabrina | C9: Gestamp | D9: Santa Isabel | E9: Relacionamento | F9: N/A | G9: C | H9: JB | I9: ERGO | J9: S | K9: =14400*12 -> 172800 | L9: R | M9: 46057 | N9: =UPPER(TEXT(A9,"MMMM")) -> JANEIRO | O9: =INT((DAY(A9)-1)/7)+1 & "ª semana" -> 3ª semana | P9: =INT((DAY(M9)-1)/7)+1 & "ª semana" -> 1ª semana
A10: 46045 | B10: Dra. Carla | C10: Bartira | D10: SBC | E10: Relacionamento | F10: N/A | G10: A | H10: JB | I10: ERGO | J10: S | K10: 25245 | L10: R | M10: 46051 | N10: =UPPER(TEXT(A10,"MMMM")) -> JANEIRO | O10: =INT((DAY(A10)-1)/7)+1 & "ª semana" -> 4ª semana | P10: =INT((DAY(M10)-1)/7)+1 & "ª semana" -> 5ª semana
A11: 46052 | B11: Regiane | C11: SUZANO | D11: Suzano | E11: Cliente ativo | F11: N/A | G11: A | H11: LS | I11: ERGO | J11: S | K11: 5154.23 | L11: P | M11: 46058 | N11: =UPPER(TEXT(A11,"MMMM")) -> JANEIRO | O11: =INT((DAY(A11)-1)/7)+1 & "ª semana" -> 5ª semana | P11: =INT((DAY(M11)-1)/7)+1 & "ª semana" -> 1ª semana
A12: 46055 | B12: Sérgio | C12: Grupo Muffato | D12: Piracicaba | E12: E-mail | F12: N/A | G12: A | H12: LS | I12: ERGO | J12: S | K12: 33265.65 | L12: P | M12: 46058 | N12: =UPPER(TEXT(A12,"MMMM")) -> FEVEREIRO | O12: =INT((DAY(A12)-1)/7)+1 & "ª semana" -> 1ª semana | P12: =INT((DAY(M12)-1)/7)+1 & "ª semana" -> 1ª semana
A13: 46055 | B13: Giovana | C13: EMS - Grupo NC | D13: Hortolândia | E13: Relacionamento | F13: N/A | G13: A | H13: JB | I13: ERGO | J13: S | K13: 50000 | L13: R | M13: 46057 | N13: =UPPER(TEXT(A13,"MMMM")) -> FEVEREIRO | O13: =INT((DAY(A13)-1)/7)+1 & "ª semana" -> 1ª semana | P13: =INT((DAY(M13)-1)/7)+1 & "ª semana" -> 1ª semana
A14: 46058 | B14: Marheny | C14: Tenaris | D14: Pindamonhangaba | E14: Cliente ativo | F14: N/A | G14: A | H14: MKT | I14: ENF | J14: S | K14: 0 | L14: R | M14: 46073 | N14: =UPPER(TEXT(A14,"MMMM")) -> FEVEREIRO | O14: =INT((DAY(A14)-1)/7)+1 & "ª semana" -> 1ª semana | P14: =INT((DAY(M14)-1)/7)+1 & "ª semana" -> 3ª semana
A15: 46058 | B15: Fernanda | C15: Clariant | D15: SP | E15: Cliente ativo | F15: N/A | G15: A | H15: LS | I15: MASSO | J15: S | K15: 3050 | L15: P | M15: 46073 | N15: =UPPER(TEXT(A15,"MMMM")) -> FEVEREIRO | O15: =INT((DAY(A15)-1)/7)+1 & "ª semana" -> 1ª semana | P15: =INT((DAY(M15)-1)/7)+1 & "ª semana" -> 3ª semana
A16: 46062 | B16: Regiane | C16: Suzano | D16: Corporativo | E16: Cliente ativo | F16: N/A | G16: A | H16: LS | I16: ERGO | J16: S | K16: 15733.41 | L16: P | M16: 46071 | N16: =UPPER(TEXT(A16,"MMMM")) -> FEVEREIRO | O16: =INT((DAY(A16)-1)/7)+1 & "ª semana" -> 2ª semana | P16: =INT((DAY(M16)-1)/7)+1 & "ª semana" -> 3ª semana
A17: 46062 | B17: Swellen | C17: Imerys | D17: Mogi das Cruzes | E17: Busca Orgânica | F17: N/A | G17: C | H17: MKT | I17: ERGO | J17: S | K17: 6820 | L17: P | M17: 46062 | N17: =UPPER(TEXT(A17,"MMMM")) -> FEVEREIRO | O17: =INT((DAY(A17)-1)/7)+1 & "ª semana" -> 2ª semana | P17: =INT((DAY(M17)-1)/7)+1 & "ª semana" -> 2ª semana
A18: 46063 | B18: Vanessa | C18: ADIUM | D18: Pindamonhangaba | E18: Busca Orgânica | F18: N/A | G18: C | H18: MKT | I18: ERGO | J18: S | K18: 24478.28 | L18: R | M18: 46064 | N18: =UPPER(TEXT(A18,"MMMM")) -> FEVEREIRO | O18: =INT((DAY(A18)-1)/7)+1 & "ª semana" -> 2ª semana | P18: =INT((DAY(M18)-1)/7)+1 & "ª semana" -> 2ª semana
A19: 46064 | B19: Vania | C19: CTG | D19: Centro-Oeste | E19: Relacionamento | F19: N/A | G19: A | H19: MKT | I19: ERGO | J19: S | K19: 36499.44 | L19: P | M19: 46065 | N19: =UPPER(TEXT(A19,"MMMM")) -> FEVEREIRO | O19: =INT((DAY(A19)-1)/7)+1 & "ª semana" -> 2ª semana | P19: =INT((DAY(M19)-1)/7)+1 & "ª semana" -> 2ª semana
A20: 46065 | B20: Bruna | C20: ECO3 | D20: Suzano | E20: Cliente ativo | F20: N/A | G20: C | H20: MKT | I20: ERGO | J20: S | K20: 7724 | L20: P | M20: 46065 | N20: =UPPER(TEXT(A20,"MMMM")) -> FEVEREIRO | O20: =INT((DAY(A20)-1)/7)+1 & "ª semana" -> 2ª semana | P20: =INT((DAY(M20)-1)/7)+1 & "ª semana" -> 2ª semana
A21: 46065 | B21: Ana Paula | C21: CLI | D21: Porto | E21: E-mail | F21: N/A | G21: C | H21: MKT | I21: GL | J21: S | K21: =3100*12 -> 37200 | L21: R | M21: 46084 | N21: =UPPER(TEXT(A21,"MMMM")) -> FEVEREIRO | O21: =INT((DAY(A21)-1)/7)+1 & "ª semana" -> 2ª semana | P21: =INT((DAY(M21)-1)/7)+1 & "ª semana" -> 1ª semana
A22: 46065 | B22: Ana Paula | C22: CLI | D22: Porto | E22: E-mail | F22: N/A | G22: C | H22: MKT | I22: FISIO | J22: S | K22: =3600*12 -> 43200 | L22: P | M22: 46084 | N22: =UPPER(TEXT(A22,"MMMM")) -> FEVEREIRO | O22: =INT((DAY(A22)-1)/7)+1 & "ª semana" -> 2ª semana | P22: =INT((DAY(M22)-1)/7)+1 & "ª semana" -> 1ª semana
A23: 46073 | B23: Luana | C23: Alcon | D23: SP | E23: Busca Orgânica | F23: N/A | G23: C | H23: MKT | I23: GL | J23: S | K23: 4494 | L23: R | M23: 46073 | N23: =UPPER(TEXT(A23,"MMMM")) -> FEVEREIRO | O23: =INT((DAY(A23)-1)/7)+1 & "ª semana" -> 3ª semana | P23: =INT((DAY(M23)-1)/7)+1 & "ª semana" -> 3ª semana
A24: 46073 | B24: Paulo Souza | C24: SET | D24: Mogi das Cruzes | E24: Parceiros | F24: N/A | G24: C | H24: MKT | I24: ERGO | J24: S | K24: 39276.97 | L24: P | M24: 46076 | N24: =UPPER(TEXT(A24,"MMMM")) -> FEVEREIRO | O24: =INT((DAY(A24)-1)/7)+1 & "ª semana" -> 3ª semana | P24: =INT((DAY(M24)-1)/7)+1 & "ª semana" -> 4ª semana
A25: 46080 | B25: Gisele | C25: Sanofi | D25: SP | E25: E-mail | F25: N/A | G25: B | H25: MKT | I25: GL | J25: S | K25: =3728*12 -> 44736 | L25: R | M25: 46086 | N25: =UPPER(TEXT(A25,"MMMM")) -> FEVEREIRO | O25: =INT((DAY(A25)-1)/7)+1 & "ª semana" -> 4ª semana | P25: =INT((DAY(M25)-1)/7)+1 & "ª semana" -> 1ª semana
A26: 46084 | B26: Isaac | C26: Rinnai | D26: Mogi das Cruzes | E26: Cliente ativo | F26: N/A | G26: C | H26: MKT | I26: ERGO | J26: S | K26: 12613.2 | L26: P | M26: 46084 | N26: =UPPER(TEXT(A26,"MMMM")) -> MARÇO | O26: =INT((DAY(A26)-1)/7)+1 & "ª semana" -> 1ª semana | P26: =INT((DAY(M26)-1)/7)+1 & "ª semana" -> 1ª semana
A27: 46090 | B27: Patrícia | C27: Caixa Residencial | D27: SP | E27: E-mail | F27: N/A | G27: C | H27: MKT | I27: MASSO | J27: S | K27: 3500 | L27: P | M27: 46090 | N27: =UPPER(TEXT(A27,"MMMM")) -> MARÇO | O27: =INT((DAY(A27)-1)/7)+1 & "ª semana" -> 2ª semana | P27: =INT((DAY(M27)-1)/7)+1 & "ª semana" -> 2ª semana
A28: 46097 | B28: BRUNNA | C28: BTP | D28: Santos | E28: E-mail | F28: N/A | G28: A | H28: MKT | I28: EVENTO | J28: S | K28: 6502.69 | L28: P | M28: 46111 | N28: =UPPER(TEXT(A28,"MMMM")) -> MARÇO | O28: =INT((DAY(A28)-1)/7)+1 & "ª semana" -> 3ª semana | P28: =INT((DAY(M28)-1)/7)+1 & "ª semana" -> 5ª semana
A29: 46099 | B29: JULIO | C29: NUBANK | D29: Corporativo | E29: E-mail | F29: N/A | G29: A | H29: MKT | I29: ERGO | J29: S | K29: =36724.44*12 -> 440693.28 | L29: R | M29: 46099 | N29: =UPPER(TEXT(A29,"MMMM")) -> MARÇO | O29: =INT((DAY(A29)-1)/7)+1 & "ª semana" -> 3ª semana | P29: =INT((DAY(M29)-1)/7)+1 & "ª semana" -> 3ª semana
A30: 46101 | B30: Everton | C30: GAT LOG | D30: Corporativo | E30: E-mail | F30: N/A | G30: C | H30: MKT | I30: ERGO | J30: S | K30: 24434.86 | L30: P | M30: 46101 | N30: =UPPER(TEXT(A30,"MMMM")) -> MARÇO | O30: =INT((DAY(A30)-1)/7)+1 & "ª semana" -> 3ª semana | P30: =INT((DAY(M30)-1)/7)+1 & "ª semana" -> 3ª semana
A31: 46107 | B31: Ana | C31: BASF | D31: Morumbi | E31: Cliente ativo | F31: N/A | G31: B | H31: MKT | I31: MASSO | J31: S | K31: 15000 | L31: P | M31: 46107 | N31: =UPPER(TEXT(A31,"MMMM")) -> MARÇO | O31: =INT((DAY(A31)-1)/7)+1 & "ª semana" -> 4ª semana | P31: =INT((DAY(M31)-1)/7)+1 & "ª semana" -> 4ª semana
A32: 46112 | B32: Dr. Ricardo | C32: DSM | D32: Campinas | E32: Relacionamento | F32: N/A | G32: A | H32: RP | I32: ERGO | J32: S | K32: 11271.49 | L32: P | M32: 46112 | N32: =UPPER(TEXT(A32,"MMMM")) -> MARÇO | O32: =INT((DAY(A32)-1)/7)+1 & "ª semana" -> 5ª semana | P32: =INT((DAY(M32)-1)/7)+1 & "ª semana" -> 5ª semana
A33: 46112 | B33: Dr. Ricardo | C33: DSM | D33: Campinas | E33: Relacionamento | F33: N/A | G33: A | H33: RP | I33: ERGO | J33: S | K33: =1500*12 -> 18000 | L33: R | M33: 46112 | N33: =UPPER(TEXT(A33,"MMMM")) -> MARÇO | O33: =INT((DAY(A33)-1)/7)+1 & "ª semana" -> 5ª semana | P33: =INT((DAY(M33)-1)/7)+1 & "ª semana" -> 5ª semana
A34: 46112 | B34: Dr. Ricardo | C34: DSM | D34: Campinas | E34: Relacionamento | F34: N/A | G34: A | H34: RP | I34: GL | J34: S | K34: =5514*12 -> 66168 | L34: R | M34: 46112 | N34: =UPPER(TEXT(A34,"MMMM")) -> MARÇO | O34: =INT((DAY(A34)-1)/7)+1 & "ª semana" -> 5ª semana | P34: =INT((DAY(M34)-1)/7)+1 & "ª semana" -> 5ª semana
A35: 46114 | B35: Marcos | C35: Inylbra | D35: Corporativo | E35: Busca Orgânica | F35: N/A | G35: C | H35: MKT | I35: ERGO | J35: S | K35: 29258.64 | L35: P | M35: 46114 | N35: =UPPER(TEXT(A35,"MMMM")) -> ABRIL | O35: =INT((DAY(A35)-1)/7)+1 & "ª semana" -> 1ª semana | P35: =INT((DAY(M35)-1)/7)+1 & "ª semana" -> 1ª semana
A36: 46114 | B36: Julia | C36: Givaudan | D36: SBC | E36: Cliente ativo | F36: N/A | G36: A | H36: LS | I36: ERGO | J36: S | K36: =2000*12 -> 24000 | L36: R | M36: 46114 | N36: =UPPER(TEXT(A36,"MMMM")) -> ABRIL | O36: =INT((DAY(A36)-1)/7)+1 & "ª semana" -> 1ª semana | P36: =INT((DAY(M36)-1)/7)+1 & "ª semana" -> 1ª semana
A37: 46114 | B37: Swellen | C37: Imerys | D37: Mogi das Cruzes | E37: Cliente ativo | F37: N/A | G37: C | H37: MKT | I37: ERGO | J37: S | K37: 27912.5 | L37: P | M37: 46114 | N37: =UPPER(TEXT(A37,"MMMM")) -> ABRIL | O37: =INT((DAY(A37)-1)/7)+1 & "ª semana" -> 1ª semana | P37: =INT((DAY(M37)-1)/7)+1 & "ª semana" -> 1ª semana
A38: 46120 | B38: Alexandre | C38: Johnsol Controls | D38: Suzano | E38: E-mail | F38: N/A | G38: A | H38: JB | I38: ERGO | J38: S | K38: 10850.57 | L38: P | M38: 46120 | N38: =UPPER(TEXT(A38,"MMMM")) -> ABRIL | O38: =INT((DAY(A38)-1)/7)+1 & "ª semana" -> 2ª semana | P38: =INT((DAY(M38)-1)/7)+1 & "ª semana" -> 2ª semana
A39: 46120 | B39: Dra. Maira | C39: Kolben | D39: Sorocaba | E39: Indicação | F39: N/A | G39: A | H39: LS | I39: ERGO | J39: S | K39: 29150 | L39: P | M39: 46120 | N39: =UPPER(TEXT(A39,"MMMM")) -> ABRIL | O39: =INT((DAY(A39)-1)/7)+1 & "ª semana" -> 2ª semana | P39: =INT((DAY(M39)-1)/7)+1 & "ª semana" -> 2ª semana
A40: 46125 | B40: André | C40: Bartira | D40: SBC | E40: Relacionamento | F40: N/A | G40: A | H40: LS | I40: ERGO | J40: S | K40: 53653.36 | L40: R | M40: 46125 | N40: =UPPER(TEXT(A40,"MMMM")) -> ABRIL | O40: =INT((DAY(A40)-1)/7)+1 & "ª semana" -> 2ª semana | P40: =INT((DAY(M40)-1)/7)+1 & "ª semana" -> 2ª semana
...

Sheet VENDAS
A1: Data | B1: Cliente | C1: Unidade | D1: Serviço | E1: Entrada | F1: Reativação? | G1: ICP | H1: Tipo | I1: Valor | J1: MÊS VENDA | K1: ORIGEM
A2: 45993 | B2: NSK | C2: Suzano | D2: ENF | E2: Novo cliente | F2: Não | G2: A | H2: R | I2: =39183.28*12 -> 470199.36 | J2: =UPPER(TEXT(A2,"mmmm")) -> DEZEMBRO | K2: NÃO SÓCIOS
A3: 45995 | B3: Lucas Meyer | C3: SP | D3: ERGO | E3: Cliente atual | F3: Não | G3: A | H3: P | I3: 2987.48 | J3: =UPPER(TEXT(A3,"mmmm")) -> DEZEMBRO | K3: NÃO SÓCIOS
A4: 45996 | B4: NSK | C4: Suzano | D4: MED | E4: Novo cliente | F4: Não | G4: A | H4: R | I4: =35000*3.5 -> 122500 | J4: =UPPER(TEXT(A4,"mmmm")) -> DEZEMBRO | K4: NÃO SÓCIOS
A5: 46003 | B5: SAINT GOBAIN | C5: Lorena | D5: ERGO | E5: Novo cliente | F5: Sim | G5: A | H5: P | I5: 5997.23 | J5: =UPPER(TEXT(A5,"mmmm")) -> DEZEMBRO | K5: NÃO SÓCIOS
A6: 46009 | B6: GERDAU | C6: Cosígua | D6: ERGO | E6: Cliente atual | F6: Sim | G6: A | H6: R | I6: =9650*12 -> 115800 | J6: =UPPER(TEXT(A6,"mmmm")) -> DEZEMBRO | K6: NÃO SÓCIOS
A7: 46050 | B7: SUZANO | C7: Suzano | D7: ERGO | E7: Cliente atual | F7: Não | G7: A | H7: P | I7: 8850 | J7: =UPPER(TEXT(A7,"mmmm")) -> JANEIRO | K7: NÃO SÓCIOS
A8: 46058 | B8: Clariant | C8: Suzano | D8: MASSO | E8: Cliente atual | F8: Não | G8: B | H8: P | I8: 1350 | J8: =UPPER(TEXT(A8,"mmmm")) -> FEVEREIRO | K8: NÃO SÓCIOS
A9: 46062 | B9: IMERYS | C9: Mogi das Cruzes | D9: ERGO | E9: Novo cliente | F9: Sim | G9: B | H9: P | I9: 6400 | J9: =UPPER(TEXT(A9,"mmmm")) -> FEVEREIRO | K9: NÃO SÓCIOS
A10: 46070 | B10: CELANESE | C10: Suzano | D10: ERGO | E10: Cliente atual | F10: Sim | G10: C | H10: P | I10: 5902.93 | J10: =UPPER(TEXT(A10,"mmmm")) -> FEVEREIRO | K10: NÃO SÓCIOS
A11: 46070 | B11: AGCO | C11: Santa Rosa/RS | D11: ERGO | E11: Cliente atual | F11: Não | G11: A | H11: R | I11: 0 | J11: =UPPER(TEXT(A11,"mmmm")) -> FEVEREIRO | K11: NÃO SÓCIOS
A12: 46071 | B12: NSK | C12: Suzano | D12: MED | E12: Novo cliente | F12: Sim | G12: A | H12: R | I12: =35000*8.5 -> 297500 | J12: =UPPER(TEXT(A12,"mmmm")) -> FEVEREIRO | K12: NÃO SÓCIOS
A13: 46090 | B13: RINNAI | C13: Mogi das Cruzes | D13: ERGO | E13: Cliente atual | F13: Sim | G13: B | H13: P | I13: 2700 | J13: =UPPER(TEXT(A13,"mmmm")) -> MARÇO | K13: NÃO SÓCIOS
A14: 46090 | B14: CAIXA | C14: SP | D14: MASSO | E14: Cliente atual | F14: Não | G14: C | H14: P | I14: 3500 | J14: =UPPER(TEXT(A14,"mmmm")) -> MARÇO | K14: NÃO SÓCIOS
A15: 46091 | B15: EMS (GRUPO NC) | C15: Hortolândia | D15: ERGO | E15: Novo cliente | F15: Sim | G15: A | H15: P | I15: 50000 | J15: =UPPER(TEXT(A15,"mmmm")) -> MARÇO | K15: SÓCIOS
A16: 46092 | B16: ADIUM | C16: Pindamonhangaba | D16: ERGO | E16: Novo cliente | F16: Sim | G16: B | H16: P | I16: 0 | J16: =UPPER(TEXT(A16,"mmmm")) -> MARÇO | K16: NÃO SÓCIOS
A17: 46092 | B17: ECO3 | C17: Suzano | D17: ERGO | E17: Cliente atual | F17: Não | G17: C | H17: P | I17: 7724 | J17: =UPPER(TEXT(A17,"mmmm")) -> MARÇO | K17: NÃO SÓCIOS
A18: 46092 | B18: SUZANO | C18: Corporativo | D18: ERGO | E18: Cliente atual | F18: Não | G18: A | H18: P | I18: 82551.61 | J18: =UPPER(TEXT(A18,"mmmm")) -> MARÇO | K18: NÃO SÓCIOS
A19: 46094 | B19: GERDAU | C19: Cotia | D19: ERGO | E19: Cliente atual | F19: Não | G19: A | H19: P | I19: =3510*3 -> 10530 | J19: =UPPER(TEXT(A19,"mmmm")) -> MARÇO | K19: NÃO SÓCIOS
A20: 46094 | B20: GERDAU | C20: Cumbica | D20: ERGO | E20: Cliente atual | F20: Não | G20: A | H20: P | I20: =4010*3 -> 12030 | J20: =UPPER(TEXT(A20,"mmmm")) -> MARÇO | K20: NÃO SÓCIOS
A21: 46094 | B21: GERDAU | C21: SJC | D21: ERGO | E21: Cliente atual | F21: Não | G21: A | H21: P | I21: =2745*3 -> 8235 | J21: =UPPER(TEXT(A21,"mmmm")) -> MARÇO | K21: NÃO SÓCIOS
A22: 46094 | B22: GERDAU | C22: Araçariguama | D22: ERGO | E22: Cliente atual | F22: Não | G22: A | H22: P | I22: =7150.12*3 -> 21450.36 | J22: =UPPER(TEXT(A22,"mmmm")) -> MARÇO | K22: NÃO SÓCIOS
A23: 46097 | B23: SUZANO | C23: Santos | D23: ERGO | E23: Cliente atual | F23: Não | G23: A | H23: P | I23: 5154.53 | J23: =UPPER(TEXT(A23,"mmmm")) -> MARÇO | K23: NÃO SÓCIOS
A24: 46100 | B24: ACRISURE | C24: SP | D24: FISIO | E24: Novo cliente | F24: Sim | G24: A | H24: R | I24: =26250*12 -> 315000 | J24: =UPPER(TEXT(A24,"mmmm")) -> MARÇO | K24: SÓCIOS
A25: 46100 | B25: VERZANI & SANDRINI | C25: Corporativo | D25: ERGO | E25: Novo cliente | F25: Sim | G25: A | H25: P | I25: 111720.51 | J25: =UPPER(TEXT(A25,"mmmm")) -> MARÇO | K25: SÓCIOS
A26: 46111 | B26: BTP | C26: Santos | D26: GL | E26: Cliente atual | F26: Não | G26: A | H26: P | I26: 1550 | J26: =UPPER(TEXT(A26,"mmmm")) -> MARÇO | K26: NÃO SÓCIOS
A27: 46111 | B27: BTP | C27: Santos | D27: AURICULO | E27: Cliente atual | F27: Não | G27: A | H27: P | I27: 2450 | J27: =UPPER(TEXT(A27,"mmmm")) -> MARÇO | K27: NÃO SÓCIOS
A28: 46125 | B28: BARTIRA | C28: SBC | D28: ERGO | E28: Novo cliente | F28: Sim | G28: A | H28: P | I28: 53653.36 | J28: =UPPER(TEXT(A28,"mmmm")) -> ABRIL | K28: SÓCIOS
A29: 46127 | B29: DSM | C29: Campinas | D29: ERGO | E29: Novo cliente | F29: Sim | G29: A | H29: R | I29: =1430*12 -> 17160 | J29: =UPPER(TEXT(A29,"mmmm")) -> ABRIL | K29: SÓCIOS
A30: 46127 | B30: DSM | C30: Campinas | D30: ERGO | E30: Novo cliente | F30: Sim | G30: A | H30: P | I30: 11271.49 | J30: =UPPER(TEXT(A30,"mmmm")) -> ABRIL | K30: SÓCIOS
A31: 46127 | B31: DSM | C31: Campinas | D31: GL | E31: Novo cliente | F31: Sim | G31: A | H31: R | I31: =6600*12 -> 79200 | J31: =UPPER(TEXT(A31,"mmmm")) -> ABRIL | K31: SÓCIOS
A32: 46135 | B32: RINNAI | C32: Mogi das Cruzes | D32: AF | E32: Cliente atual | F32: Sim | G32: B | H32: P | I32: 1200 | J32: =UPPER(TEXT(A32,"mmmm")) -> ABRIL | K32: NÃO SÓCIOS
A33: 46135 | B33: RINNAI | C33: Mogi das Cruzes | D33: AF | E33: Cliente atual | F33: Sim | G33: B | H33: P | I33: 500 | J33: =UPPER(TEXT(A33,"mmmm")) -> ABRIL | K33: NÃO SÓCIOS
A34: 46135 | B34: RINNAI | C34: Mogi das Cruzes | D34: AF | E34: Cliente atual | F34: Sim | G34: B | H34: P | I34: 17561.7 | J34: =UPPER(TEXT(A34,"mmmm")) -> ABRIL | K34: NÃO SÓCIOS
A35: 46135 | B35: RINNAI | C35: Mogi das Cruzes | D35: AF | E35: Cliente atual | F35: Sim | G35: B | H35: P | I35: 2340 | J35: =UPPER(TEXT(A35,"mmmm")) -> ABRIL | K35: NÃO SÓCIOS
A36: 46135 | B36: RINNAI | C36: Mogi das Cruzes | D36: MASSO | E36: Cliente atual | F36: Sim | G36: B | H36: P | I36: 3400 | J36: =UPPER(TEXT(A36,"mmmm")) -> ABRIL | K36: NÃO SÓCIOS
A37: 46136 | B37: VALLOUREC | C37: Corporativo | D37: ERGO | E37: Novo cliente | F37: Sim | G37: A | H37: P | I37: 100766.92 | J37: =UPPER(TEXT(A37,"mmmm")) -> ABRIL | K37: NÃO SÓCIOS
A38: 46136 | B38: VALLOUREC | C38: Corporativo | D38: ERGO | E38: Novo cliente | F38: Sim | G38: A | H38: R | I38: =5379.53*12 -> 64554.36 | J38: =UPPER(TEXT(A38,"mmmm")) -> ABRIL | K38: NÃO SÓCIOS
A39: 46153 | B39: KOLBEN | C39: Sorocaba | D39: ERGO | E39: Novo cliente | F39: Sim | G39: A | H39: P | I39: 29150 | J39: =UPPER(TEXT(A39,"mmmm")) -> MAIO | K39: NÃO SÓCIOS
A40: 46164 | B40: LYB | C40: Pindamonhangaba | D40: ERGO | E40: Novo cliente | F40: Sim | G40: C | H40: P | I40: 25500 | J40: =UPPER(TEXT(A40,"mmmm")) -> MAIO | K40: SÓCIOS

Sheet EVENTOS
A1: EVENTO | B1: Data | C1: Lead captados | D1: reuniões | E1: % | F1: propostas | G1: %2 | H1: fechamentos | I1: %22
A2: CBQV | B2: 45931 | C2: 118 | D2: 4 | E2: =D2/C2 -> 0.033898305 | F2: 4 | G2: =F2/D2 -> 1 | H2: 1 | I2: =H2/F2 -> 0.25
A3: AMCHAM (CN) | B3: 45901 | C3: 6 | D3: 1 | E3: =D3/C3 -> 0.16666667 | F3: 1 | G3: =F3/D3 -> 1 | H3: 0 | I3: =H3/F3 -> 0
A4: SINDUSFARMA | B4: 45901 | C4: 4 | D4: 0 | E4: =D4/C4 -> 0 | F4: 1 | G4: =F4/D4 -> #DIV/0! | I4: =H4/F4 -> 0
A5: AMCHAM (BENCH) | B5: 45931 | E5: =D5/C5 -> #DIV/0! | G5: =F5/D5 -> #DIV/0! | I5: =H5/F5 -> #DIV/0!

Sheet ACUMULADO
A1: META DE VENDAS | B1: JANEIRO | C1: FEVEREIRO | D1: MARÇO | E1: ABRIL | F1: MAIO | G1: JUNHO | H1: JULHO | I1: AGOSTO | J1: SETEMBRO | K1: OUTUBRO | L1: NOVEMBRO | M1: DEZEMBRO | N1: ACUMULADO | P1: Q1/2026 | R1: RESULTADO% | S1: Q2/2026 | U1: RESULTADO% | V1: Q3/2026 | X1: RESULTADO% | Y1: Q4/2026 | AA1: RESULTADO%
A2: VENDAS RECORRENTES | B2: =B8/B5 -> 0.0331875 | C2: =C7/C5 -> 1.115625 | D2: =D7/D5 -> 1.18125 | E2: =E7/E5 -> 0.60342885 | F2: =F7/F5 -> 0 | G2: =G7/G5 -> 0 | H2: =H7/H5 -> 0 | I2: =I7/I5 -> 0 | J2: =J7/J5 -> 0 | ... N2: =N7/N5 -> 0.46309804 | P2: META PREVISTA | Q2: RESULTADO | R2: % | S2: META PREVISTA | T2: RESULTADO | U2: % | V2: META PREVISTA | W2: RESULTADO | X2: % | Y2: META PREVISTA | Z2: RESULTADO | AA2: %
A3: VENDAS PONTUAIS | B3: =B8/B6 -> 0.13275 | C3: =C8/C6 -> 0.20479395 | D3: =D8/D6 -> 4.7939401 | E3: =E8/E6 -> 2.860402 | F3: =F8/F6 -> 0.81975 | G3: =G8/G6 -> 0 | H3: =H8/H6 -> 0 | I3: =I8/I6 -> 0 | ... N3: =N8/N6 -> 0.7455339 | P3: =SUM(E15:F17) -> 1000000 | Q3: =SUM(G15:H17) -> 954598.94 | R3: =Q3/P3 -> 0.95459894 | S3: =SUM(E18:F20) -> 1000000 | T3: =SUM(G18:H20) -> 406257.83 | U3: =T3/S3 -> 0.40625783 | V3: =SUM(E21:F23) -> 1000000 | W3: =SUM(G21:H23) -> 0 | X3: =W3/V3 -> 0 | Y3: =SUM(E24:F26) -> 1000000 | Z3: =SUM(G24:H26) -> 717484.07 | AA3: =Z3/Y3 -> 0.71748407
A4: META TOTAL | B4: =(B8+B7)/(B6+B5) -> 0.02655 | C4: =(C7+C8)/(C6+C5) -> 0.93345879 | D4: =(D7+D8)/(D6+D5) -> 1.903788 | E4: =(E7+E8)/(E6+E5) -> 1.0548235 | F4: =(F7+F8)/(F6+F5) -> 0.16395 | G4: =(G7+G8)/(G6+G5) -> 0 | H4: =(H7+H8)/(H6+H5) -> 0 | I4: =(I7+I8)/(I6+I5) -> 0 | J4: =(J7+J8)/(J6+J5) -> 0 | ... N4: =(N7+N8)/(N6+N5) -> 0.51958521
A5: META PREVISTA RECORRENTES | B5: 266666.67 | C5: 266666.67 | D5: 266666.67 | E5: 266666.67 | F5: 266666.67 | G5: 266666.67 | H5: 266666.67 | I5: 266666.67 | J5: 266666.67 | K5: 266666.67 | L5: 266666.67 | M5: 266666.67 | N5: =SUM(BASE_ACUM_VENDAS[[#This Row],[JANEIRO]:[DEZEMBRO]]) -> 3200000
A6: META PREVISTA PONTUAIS | B6: 66666.667 | C6: 66666.667 | D6: 66666.667 | E6: 66666.667 | F6: 66666.667 | G6: 66666.667 | H6: 66666.667 | I6: 66666.667 | J6: 66666.667 | K6: 66666.667 | L6: 66666.667 | M6: 66666.667 | N6: =SUM(BASE_ACUM_VENDAS[[#This Row],[JANEIRO]:[DEZEMBRO]]) -> 800000
A7: VENDAS RECORRENTES | C7: =SUMIFS(VENDAS!$I:$I, VENDAS!$H:$H, "R", VENDAS!$J:$J, C$1) -> 297500 | D7: =SUMIFS(VENDAS!$I:$I, VENDAS!$H:$H, "R", VENDAS!$J:$J, D$1) -> 315000 | E7: =SUMIFS(VENDAS!$I:$I, VENDAS!$H:$H, "R", VENDAS!$J:$J, E$1) -> 160914.36 | F7: =SUMIFS(VENDAS!$I:$I, VENDAS!$H:$H, "R", VENDAS!$J:$J, F$1) -> 0 | G7: =SUMIFS(VENDAS!$I:$I, VENDAS!$H:$H, "R", VENDAS!$J:$J, G$1) -> 0 | H7: =SUMIFS(VENDAS!$I:$I, VENDAS!$H:$H, "R", VENDAS!$J:$J, H$1) -> 0 | I7: =SUMIFS(VENDAS!$I:$I, VENDAS!$H:$H, "R", VENDAS!$J:$J, I$1) -> 0 | J7: =SUMIFS(VENDAS!$I:$I, VENDAS!$H:$H, "R", VENDAS!$J:$J, J$1) -> 0 | ... M7: =SUMIFS(VENDAS!$I:$I, VENDAS!$H:$H, "R", VENDAS!$J:$J, M$1) -> 708499.36 | N7: =SUM(BASE_ACUM_VENDAS[[#This Row],[JANEIRO]:[DEZEMBRO]]) -> 1481913.7
A8: VENDAS PONTUAIS | B8: =SUMIFS(VENDAS!$I:$I, VENDAS!$H:$H, "P", VENDAS!$J:$J, B$1) -> 8850 | C8: =SUMIFS(VENDAS!$I:$I, VENDAS!$H:$H, "P", VENDAS!$J:$J, C$1) -> 13652.93 | D8: =SUMIFS(VENDAS!$I:$I, VENDAS!$H:$H, "P", VENDAS!$J:$J, D$1) -> 319596.01 | E8: =SUMIFS(VENDAS!$I:$I, VENDAS!$H:$H, "P", VENDAS!$J:$J, E$1) -> 190693.47 | F8: =SUMIFS(VENDAS!$I:$I, VENDAS!$H:$H, "P", VENDAS!$J:$J, F$1) -> 54650 | G8: =SUMIFS(VENDAS!$I:$I, VENDAS!$H:$H, "P", VENDAS!$J:$J, G$1) -> 0 | H8: =SUMIFS(VENDAS!$I:$I, VENDAS!$H:$H, "P", VENDAS!$J:$J, H$1) -> 0 | I8: =SUMIFS(VENDAS!$I:$I, VENDAS!$H:$H, "P", VENDAS!$J:$J, I$1) -> 0 | ... M8: =SUMIFS(VENDAS!$I:$I, VENDAS!$H:$H, "P", VENDAS!$J:$J, M$1) -> 8984.71 | N8: =SUM(BASE_ACUM_VENDAS[[#This Row],[JANEIRO]:[DEZEMBRO]]) -> 596427.12
A9: VENDAS ORIGINADAS SÓCIOS | B9: =SUMIFS(VENDAS!$I:$I, VENDAS!$K:$K, "SÓCIOS", VENDAS!$J:$J, B$1) -> 0 | C9: =SUMIFS(VENDAS!$I:$I, VENDAS!$K:$K, "SÓCIOS", VENDAS!$J:$J, C$1) -> 0 | D9: =SUMIFS(VENDAS!$I:$I, VENDAS!$K:$K, "SÓCIOS", VENDAS!$J:$J, D$1) -> 476720.51 | E9: =SUMIFS(VENDAS!$I:$I, VENDAS!$K:$K, "SÓCIOS", VENDAS!$J:$J, E$1) -> 161284.85 | F9: =SUMIFS(VENDAS!$I:$I, VENDAS!$K:$K, "SÓCIOS", VENDAS!$J:$J, F$1) -> 25500 | G9: =SUMIFS(VENDAS!$I:$I, VENDAS!$K:$K, "SÓCIOS", VENDAS!$J:$J, G$1) -> 0 | H9: =SUMIFS(VENDAS!$I:$I, VENDAS!$K:$K, "SÓCIOS", VENDAS!$J:$J, H$1) -> 0 | I9: =SUMIFS(VENDAS!$I:$I, VENDAS!$K:$K, "SÓCIOS", VENDAS!$J:$J, I$1) -> 0 | ... M9: =SUMIFS(VENDAS!$I:$I, VENDAS!$K:$K, "SÓCIOS", VENDAS!$J:$J, M$1) -> 0 | N9: =SUM(BASE_ACUM_VENDAS[[#This Row],[JANEIRO]:[DEZEMBRO]]) -> 663505.36
A11: META Anual | B11: 4000000 | C11: =B11/12 -> 333333.33 | D11: PROSPEC | E11: 0.6 | F11: =C11*E11 -> 200000
B12: =(SUM(B7:M8)/$B11) -> 0.51958521 | D12: SÓCIOS | E12: 0.4 | F12: =C11*E12 -> 133333.33
B14: NOVOS RECOR. | C14: PONTUAIS | D14: META TOTAL | E14: META RECOR. | F14: META PONT. | G14: VENDAS RECOR. | H14: VENDAS PONT.
A15: JANEIRO | B15: =G15/E15 -> 0 | C15: =H15/F15 -> 0.13275 | D15: =(H15+G15)/(F15+E15) -> 0.02655 | E15: 266666.67 | F15: 66666.667 | G15: =B7 -> 0 | H15: =B8 -> 8850
A16: FEVEREIRO | B16: =G16/E16 -> 1.115625 | C16: =H16/F16 -> 0.20479395 | D16: =(H16+G16)/(F16+E16) -> 0.93345879 | E16: 266666.67 | F16: 66666.667 | G16: =C7 -> 297500 | H16: =C8 -> 13652.93
A17: MARÇO | B17: =G17/E17 -> 1.18125 | C17: =H17/F17 -> 4.7939401 | D17: =(H17+G17)/(F17+E17) -> 1.903788 | E17: 266666.67 | F17: 66666.667 | G17: =D7 -> 315000 | H17: =D8 -> 319596.01
A18: ABRIL | B18: =G18/E18 -> 0.60342885 | C18: =H18/F18 -> 2.860402 | D18: =(H18+G18)/(F18+E18) -> 1.0548235 | E18: 266666.67 | F18: 66666.667 | G18: =E7 -> 160914.36 | H18: =E8 -> 190693.47
A19: MAIO | B19: =G19/E19 -> 0 | C19: =H19/F19 -> 0.81975 | D19: =(H19+G19)/(F19+E19) -> 0.16395 | E19: 266666.67 | F19: 66666.667 | G19: =F7 -> 0 | H19: =F8 -> 54650
A20: JUNHO | B20: =G20/E20 -> 0 | C20: =H20/F20 -> 0 | D20: =(H20+G20)/(F20+E20) -> 0 | E20: 266666.67 | F20: 66666.667 | G20: =G7 -> 0 | H20: =G8 -> 0
A21: JULHO | B21: =G21/E21 -> 0 | C21: =H21/F21 -> 0 | D21: =(H21+G21)/(F21+E21) -> 0 | E21: 266666.67 | F21: 66666.667 | G21: =H7 -> 0 | H21: =H8 -> 0
A22: AGOSTO | B22: =G22/E22 -> 0 | C22: =H22/F22 -> 0 | D22: =(H22+G22)/(F22+E22) -> 0 | E22: 266666.67 | F22: 66666.667 | G22: =I7 -> 0 | H22: =I8 -> 0
A23: SETEMBRO | B23: =G23/E23 -> 0 | C23: =H23/F23 -> 0 | D23: =(H23+G23)/(F23+E23) -> 0 | E23: 266666.67 | F23: 66666.667 | G23: =J7 -> 0 | H23: =J8 -> 0
A24: OUTUBRO | B24: =G24/E24 -> 0 | C24: =H24/F24 -> 0 | D24: =(H24+G24)/(F24+E24) -> 0 | E24: 266666.67 | F24: 66666.667 | G24: =K7 -> 0 | H24: =K8 -> 0
A25: NOVEMBRO | B25: =G25/E25 -> 0 | C25: =H25/F25 -> 0 | D25: =(H25+G25)/(F25+E25) -> 0 | E25: 266666.67 | F25: 66666.667 | G25: =L7 -> 0 | H25: =L8 -> 0
A26: DEZEMBRO | B26: =G26/E26 -> 2.6568726 | C26: =H26/F26 -> 0.13477065 | D26: =(H26+G26)/(F26+E26) -> 2.1524522 | E26: 266666.67 | F26: 66666.667 | G26: =M7 -> 708499.36 | H26: =M8 -> 8984.71
A27: =BASE_ACUM_VENDAS[[#Headers],[ACUMULADO]] -> ACUMULADO | B27: =N2 -> 0.46309804 | C27: =N3 -> 0.7455339 | D27: =N4 -> 0.51958521 | E27: =SUM(E15:E26) -> 3200000 | F27: =SUM(F15:F26) -> 800000 | G27: =N7 -> 1481913.7 | H27: =N8 -> 596427.12

Sheet ANÁLISE
A1: Rótulos de Linha | B1: Contagem de Proposta Enviada ? | BX1: Data (Trimestre) | BY1: All
A2: S | B2: 54
A3: Total Geral | B3: 54 | BY3: Rótulos de Coluna
BY4: jan | BZ4: fev | CA4: mar | CB4: abr | CC4: mai | CD4: Total Geral
AQ5: Rótulos de Linha | BX5: Contagem de Proposta Enviada ? | BY5: 7 | BZ5: 14 | CA5: 12 | CB5: 10 | CC5: 11 | CD5: 54
AQ6: jan
AQ7: fev
AQ8: mar
AQ9: abr
AQ10: mai
AQ11: Total Geral
A57: Data (Mês) | B57: All
B59: Rótulos de Coluna
A60: Rótulos de Linha | B60: AF | C60: AURICULO | D60: ENF | E60: ERGO | F60: FISIO | G60: GL | H60: MASSO | I60: MED | J60: Total Geral
A61: ACRISURE
A62: ADIUM
A63: AGCO
A64: BARTIRA
A65: BTP
A66: CAIXA
A67: CELANESE
A68: Clariant
A69: DSM
A70: ECO3
A71: EMS (GRUPO NC)
A72: GERDAU
... A83: Total Geral
AU91: Contagem de Proposta Enviada ? | AV91: Rótulos de Coluna
AU92: Rótulos de Linha | AV92: jan | AW92: fev | AX92: mar | AY92: abr | AZ92: mai | BA92: Total Geral
AU93: S | AV93: 10 | AW93: 14 | AX93: 9 | AY93: 11 | AZ93: 10 | BA93: 54
AU94: Total Geral | AV94: 10 | AW94: 14 | AX94: 9 | AY94: 11 | AZ94: 10 | BA94: 54
CA101: Data | CB101: All
CB103: Rótulos de Coluna
CB104: jan | CC104: fev | CD104: mar | CE104: abr | CF104: mai | CG104: dez | CH104: Total Geral
CA105: Soma de Valor | CB105: 8850 | CC105: 311152.93 | CD105: 634596.01 | CE105: 351607.83 | CF105: 54650 | CG105: 717484.07 | CH105: 2078340.8
A152: Contagem de Semana Envio | B152: Rótulos de Coluna
A153: Rótulos de Linha | B153: 1ª semana | C153: 2ª semana | D153: 3ª semana | E153: 4ª semana | F153: 5ª semana | G153: Total Geral
A154: jan | D154: 5 | E154: 1 | F154: 1 | G154: 7
A155: fev | B155: 5 | C155: 4 | D155: 4 | E155: 1 | G155: 14
A156: mar | B156: 4 | C156: 1 | D156: 2 | E156: 1 | F156: 4 | G156: 12
...
